Traceback (most recent call last):
  File "C:\Users\seanc\AppData\Roaming\Python\Python38\site-packages\jupyter_cache\executors\utils.py", line 51, in single_nb_execution
    executenb(
  File "C:\Users\seanc\AppData\Roaming\Python\Python38\site-packages\nbclient\client.py", line 1117, in execute
    return NotebookClient(nb=nb, resources=resources, km=km, **kwargs).execute()
  File "C:\Users\seanc\AppData\Roaming\Python\Python38\site-packages\nbclient\util.py", line 78, in wrapped
    return just_run(coro(*args, **kwargs))
  File "C:\Users\seanc\AppData\Roaming\Python\Python38\site-packages\nbclient\util.py", line 57, in just_run
    return loop.run_until_complete(coro)
  File "c:\program files\python38\lib\asyncio\base_events.py", line 616, in run_until_complete
    return future.result()
  File "C:\Users\seanc\AppData\Roaming\Python\Python38\site-packages\nbclient\client.py", line 558, in async_execute
    await self.async_execute_cell(
  File "C:\Users\seanc\AppData\Roaming\Python\Python38\site-packages\nbclient\client.py", line 862, in async_execute_cell
    self._check_raise_for_error(cell, exec_reply)
  File "C:\Users\seanc\AppData\Roaming\Python\Python38\site-packages\nbclient\client.py", line 765, in _check_raise_for_error
    raise CellExecutionError.from_cell_and_msg(cell, exec_reply_content)
nbclient.exceptions.CellExecutionError: An error occurred while executing the following cell:
------------------
#The rolling values for the 95 sets are more difficult as 95 is not divisible by 10
inter_win_95=(win_95.rolling(window=10, axis=1).sum()).iloc[:,[9,18,27,28,37,46,47,56,65,66,75,84,85, 94]]

#Finding the rolling sum for 9th column
wins_95_col8=(win_95.rolling(window=9, axis=1).sum()).iloc[:,8]

#Calculating the average of intermediate columns as new column
Wins_9_5=(wins_95_col8+inter_95.iloc[:,0])/2
Wins_28_5=(inter_95.iloc[:,2]+inter_95.iloc[:,3])/2
Wins_47_5=(inter_95.iloc[:,5]+inter_95.iloc[:,6])/2
Wins_66_5=(inter_95.iloc[:,8]+inter_95.iloc[:,9])/2
Wins_85_5=(inter_95.iloc[:,11]+inter_95.iloc[:,12])/2

#Add everything together
inter_win_95=pd.concat([inter_win_95, Wins_9_5.rename("Wins_9_5"), Wins_28_5.rename("Wins_28_5"), 
                        Wins_47_5.rename("Wins_47_5"),Wins_66_5.rename("Wins_66_5"),
                        Wins_85_5.rename("Wins_85_5")], axis=1)

#Reorganise columns
cols = inter_win_95.columns.tolist()
rolling_win_95 = inter_win_95[[cols[-5], cols[1], cols[-4], cols[4], cols[-3], cols[7], cols[-2], cols[10], cols[-1], cols[13]]]
------------------

[1;31m---------------------------------------------------------------------------[0m
[1;31mNameError[0m                                 Traceback (most recent call last)
[1;32m~\AppData\Local\Temp/ipykernel_3992/4266475338.py[0m in [0;36m<module>[1;34m[0m
[0;32m      6[0m [1;33m[0m[0m
[0;32m      7[0m [1;31m#Calculating the average of intermediate columns as new column[0m[1;33m[0m[1;33m[0m[1;33m[0m[0m
[1;32m----> 8[1;33m [0mWins_9_5[0m[1;33m=[0m[1;33m([0m[0mwins_95_col8[0m[1;33m+[0m[0minter_95[0m[1;33m.[0m[0miloc[0m[1;33m[[0m[1;33m:[0m[1;33m,[0m[1;36m0[0m[1;33m][0m[1;33m)[0m[1;33m/[0m[1;36m2[0m[1;33m[0m[1;33m[0m[0m
[0m[0;32m      9[0m [0mWins_28_5[0m[1;33m=[0m[1;33m([0m[0minter_95[0m[1;33m.[0m[0miloc[0m[1;33m[[0m[1;33m:[0m[1;33m,[0m[1;36m2[0m[1;33m][0m[1;33m+[0m[0minter_95[0m[1;33m.[0m[0miloc[0m[1;33m[[0m[1;33m:[0m[1;33m,[0m[1;36m3[0m[1;33m][0m[1;33m)[0m[1;33m/[0m[1;36m2[0m[1;33m[0m[1;33m[0m[0m
[0;32m     10[0m [0mWins_47_5[0m[1;33m=[0m[1;33m([0m[0minter_95[0m[1;33m.[0m[0miloc[0m[1;33m[[0m[1;33m:[0m[1;33m,[0m[1;36m5[0m[1;33m][0m[1;33m+[0m[0minter_95[0m[1;33m.[0m[0miloc[0m[1;33m[[0m[1;33m:[0m[1;33m,[0m[1;36m6[0m[1;33m][0m[1;33m)[0m[1;33m/[0m[1;36m2[0m[1;33m[0m[1;33m[0m[0m

[1;31mNameError[0m: name 'inter_95' is not defined
NameError: name 'inter_95' is not defined

